<sdf version='1.6'>
  <world name='default'>
    <light name='sun' type='directional'>
      <cast_shadows>1</cast_shadows>
      <pose frame=''>0 0 10 0 -0 0</pose>
      <diffuse>0.8 0.8 0.8 1</diffuse>
      <specular>0.2 0.2 0.2 1</specular>
      <attenuation>
        <range>1000</range>
        <constant>0.9</constant>
        <linear>0.01</linear>
        <quadratic>0.001</quadratic>
      </attenuation>
      <direction>-0.5 0.1 -0.9</direction>
    </light>
    <model name='ground_plane'>
      <static>1</static>
      <link name='link'>
        <collision name='collision'>
          <geometry>
            <plane>
              <normal>0 0 1</normal>
              <size>100 100</size>
            </plane>
          </geometry>
          <surface>
            <friction>
              <ode>
                <mu>100</mu>
                <mu2>50</mu2>
              </ode>
              <torsional>
                <ode/>
              </torsional>
            </friction>
            <contact>
              <ode/>
            </contact>
            <bounce/>
          </surface>
          <max_contacts>10</max_contacts>
        </collision>
        <visual name='visual'>
          <cast_shadows>0</cast_shadows>
          <geometry>
            <plane>
              <normal>0 0 1</normal>
              <size>100 100</size>
            </plane>
          </geometry>
          <material>
            <script>
              <uri>file://media/materials/scripts/gazebo.material</uri>
              <name>Gazebo/Grey</name>
            </script>
          </material>
        </visual>
        <self_collide>0</self_collide>
        <enable_wind>0</enable_wind>
        <kinematic>0</kinematic>
      </link>
    </model>
    <gravity>0 0 -9.8</gravity>
    <magnetic_field>6e-06 2.3e-05 -4.2e-05</magnetic_field>
    <atmosphere type='adiabatic'/>
    <physics name='default_physics' default='0' type='ode'>
      <max_step_size>0.001</max_step_size>
      <real_time_factor>1</real_time_factor>
      <real_time_update_rate>1000</real_time_update_rate>
    </physics>
    <scene>
      <ambient>0.4 0.4 0.4 1</ambient>
      <background>0.7 0.7 0.7 1</background>
      <shadows>1</shadows>
    </scene>
    <audio>
      <device>default</device>
    </audio>
    <wind/>
    <spherical_coordinates>
      <surface_model>EARTH_WGS84</surface_model>
      <latitude_deg>0</latitude_deg>
      <longitude_deg>0</longitude_deg>
      <elevation>0</elevation>
      <heading_deg>0</heading_deg>
    </spherical_coordinates>
    <model name='table'>
      <static>1</static>
      <link name='link'>
        <collision name='surface'>
          <pose frame=''>0 0 1 0 -0 0</pose>
          <geometry>
            <box>
              <size>1.5 0.8 0.03</size>
            </box>
          </geometry>
          <surface>
            <friction>
              <ode>
                <mu>0.6</mu>
                <mu2>0.6</mu2>
              </ode>
              <torsional>
                <ode/>
              </torsional>
            </friction>
            <contact>
              <ode/>
            </contact>
            <bounce/>
          </surface>
          <max_contacts>10</max_contacts>
        </collision>
        <visual name='visual1'>
          <pose frame=''>0 0 1 0 -0 0</pose>
          <geometry>
            <box>
              <size>1.5 0.8 0.03</size>
            </box>
          </geometry>
          <material>
            <script>
              <uri>file://media/materials/scripts/gazebo.material</uri>
              <name>Gazebo/Wood</name>
            </script>
          </material>
        </visual>
        <collision name='front_left_leg'>
          <pose frame=''>0.68 0.38 0.5 0 -0 0</pose>
          <geometry>
            <cylinder>
              <radius>0.02</radius>
              <length>1</length>
            </cylinder>
          </geometry>
          <max_contacts>10</max_contacts>
          <surface>
            <contact>
              <ode/>
            </contact>
            <bounce/>
            <friction>
              <torsional>
                <ode/>
              </torsional>
              <ode/>
            </friction>
          </surface>
        </collision>
        <visual name='front_left_leg'>
          <pose frame=''>0.68 0.38 0.5 0 -0 0</pose>
          <geometry>
            <cylinder>
              <radius>0.02</radius>
              <length>1</length>
            </cylinder>
          </geometry>
          <material>
            <script>
              <uri>file://media/materials/scripts/gazebo.material</uri>
              <name>Gazebo/Grey</name>
            </script>
          </material>
        </visual>
        <collision name='front_right_leg'>
          <pose frame=''>0.68 -0.38 0.5 0 -0 0</pose>
          <geometry>
            <cylinder>
              <radius>0.02</radius>
              <length>1</length>
            </cylinder>
          </geometry>
          <max_contacts>10</max_contacts>
          <surface>
            <contact>
              <ode/>
            </contact>
            <bounce/>
            <friction>
              <torsional>
                <ode/>
              </torsional>
              <ode/>
            </friction>
          </surface>
        </collision>
        <visual name='front_right_leg'>
          <pose frame=''>0.68 -0.38 0.5 0 -0 0</pose>
          <geometry>
            <cylinder>
              <radius>0.02</radius>
              <length>1</length>
            </cylinder>
          </geometry>
          <material>
            <script>
              <uri>file://media/materials/scripts/gazebo.material</uri>
              <name>Gazebo/Grey</name>
            </script>
          </material>
        </visual>
        <collision name='back_right_leg'>
          <pose frame=''>-0.68 -0.38 0.5 0 -0 0</pose>
          <geometry>
            <cylinder>
              <radius>0.02</radius>
              <length>1</length>
            </cylinder>
          </geometry>
          <max_contacts>10</max_contacts>
          <surface>
            <contact>
              <ode/>
            </contact>
            <bounce/>
            <friction>
              <torsional>
                <ode/>
              </torsional>
              <ode/>
            </friction>
          </surface>
        </collision>
        <visual name='back_right_leg'>
          <pose frame=''>-0.68 -0.38 0.5 0 -0 0</pose>
          <geometry>
            <cylinder>
              <radius>0.02</radius>
              <length>1</length>
            </cylinder>
          </geometry>
          <material>
            <script>
              <uri>file://media/materials/scripts/gazebo.material</uri>
              <name>Gazebo/Grey</name>
            </script>
          </material>
        </visual>
        <collision name='back_left_leg'>
          <pose frame=''>-0.68 0.38 0.5 0 -0 0</pose>
          <geometry>
            <cylinder>
              <radius>0.02</radius>
              <length>1</length>
            </cylinder>
          </geometry>
          <max_contacts>10</max_contacts>
          <surface>
            <contact>
              <ode/>
            </contact>
            <bounce/>
            <friction>
              <torsional>
                <ode/>
              </torsional>
              <ode/>
            </friction>
          </surface>
        </collision>
        <visual name='back_left_leg'>
          <pose frame=''>-0.68 0.38 0.5 0 -0 0</pose>
          <geometry>
            <cylinder>
              <radius>0.02</radius>
              <length>1</length>
            </cylinder>
          </geometry>
          <material>
            <script>
              <uri>file://media/materials/scripts/gazebo.material</uri>
              <name>Gazebo/Grey</name>
            </script>
          </material>
        </visual>
        <self_collide>0</self_collide>
        <enable_wind>0</enable_wind>
        <kinematic>0</kinematic>
      </link>
      <pose frame=''>0.286971 -0.023322 0 0 -0 0</pose>
    </model>
    <state world_name='default'>
      <sim_time>526 927000000</sim_time>
      <real_time>49 772996797</real_time>
      <wall_time>1658226327 697079878</wall_time>
      <iterations>18940</iterations>
      <model name='ground_plane'>
        <pose frame=''>0 0 0 0 -0 0</pose>
        <scale>1 1 1</scale>
        <link name='link'>
          <pose frame=''>0 0 0 0 -0 0</pose>
          <velocity>0 0 0 0 -0 0</velocity>
          <acceleration>0 0 0 0 -0 0</acceleration>
          <wrench>0 0 0 0 -0 0</wrench>
        </link>
      </model>
      <model name='robotic_arm'>
        <pose frame=''>-0 -0 1.06 0 -0 0</pose>
        <scale>1 1 1</scale>
        <link name='arm_1_1'>
          <pose frame=''>-0.0022 -0.000197 1.16675 -1.89404 1.3e-05 -0.000732</pose>
          <velocity>0.000142 2.4e-05 -7.2e-05 -0.007364 -0.006215 -0.000351</velocity>
          <acceleration>0.125967 -0.218828 -0.463547 1.22327 1.20003 -2.93106</acceleration>
          <wrench>0.01006 -0.017476 -0.037019 0 -0 0</wrench>
        </link>
        <link name='arm_2_1'>
          <pose frame=''>0.001081 0.113586 1.12863 0.908108 -0.000133 -0.000691</pose>
          <velocity>0.000596 -0.000237 -0.000856 0.051663 0.005731 -0.005019</velocity>
          <acceleration>0.321831 -1.29194 -2.09865 -1.37247 -1.36065 0.9755</acceleration>
          <wrench>0.036719 -0.147402 -0.239442 0 -0 0</wrench>
        </link>
        <link name='arm_3_1'>
          <pose frame=''>-0.009677 0.046101 1.18803 -0.906606 0.061933 -3.09394</pose>
          <velocity>0.000724 -0.003224 -0.004263 0.051849 0.02736 -0.021619</velocity>
          <acceleration>0.577107 -4.11764 -4.8818 -2.74379 1.2401 -0.311874</acceleration>
          <wrench>0.017046 -0.12162 -0.14419 0 -0 0</wrench>
        </link>
        <link name='base_link'>
          <pose frame=''>-0 0 1.06 0 2e-06 0</pose>
          <velocity>3e-06 2e-06 -1e-06 0.000134 -0.000199 0.000136</velocity>
          <acceleration>-0.00125 0.001828 -0.000169 -0.130032 -0.05181 0.036547</acceleration>
          <wrench>-0.000303 0.000444 -4.1e-05 0 -0 0</wrench>
        </link>
        <link name='camera_rgb_frame'>
          <pose frame=''>0 0 2.06 0 1.25 1.54</pose>
          <velocity>0 0 -0 0 -0 0</velocity>
          <acceleration>0 0 0 0 -0 0</acceleration>
          <wrench>0 0 0 0 -0 0</wrench>
        </link>
        <link name='flange_adaptor_2'>
          <pose frame=''>-0.025389 0.024828 1.20943 -1.21327 0.062 -3.09402</pose>
          <velocity>0.000922 -0.004 -0.005049 0.136387 0.03039 -0.017157</velocity>
          <acceleration>0.500739 -4.49491 -8.17411 2.98101 1.12518 1.18732</acceleration>
          <wrench>0.037455 -0.336219 -0.611423 0 -0 0</wrench>
        </link>
        <link name='grip_finger_left_2'>
          <pose frame=''>-0.067169 -0.028038 1.19102 -1.21327 0.061808 -3.09406</pose>
          <velocity>0.000275 0.000576 -0.008468 0.138346 -0.017429 -0.008878</velocity>
          <acceleration>1.40857 -1.48277 -9.52321 -1.78432 -0.720933 -1.7754</acceleration>
          <wrench>0.014486 -0.015249 -0.09794 0 -0 0</wrench>
        </link>
        <link name='grip_finger_right_2'>
          <pose frame=''>-0.071167 -0.009443 1.24114 -1.21327 0.062017 -3.09402</pose>
          <velocity>0.000296 -0.002889 0.004135 0.135738 0.029852 -0.016995</velocity>
          <acceleration>0.080311 -3.69301 1.37021 0.18722 1.39374 -1.40102</acceleration>
          <wrench>0.0007 -0.032208 0.01195 0 -0 0</wrench>
        </link>
        <link name='waist_1'>
          <pose frame=''>0.001 -0.0002 1.12 0 -2e-06 -0.000733</pose>
          <velocity>2.9e-05 3.6e-05 2.2e-05 -0.000633 0.000371 0.000182</velocity>
          <acceleration>0.019717 -0.042498 0.012949 1.02773 0.65017 0.791711</acceleration>
          <wrench>0.003172 -0.006837 0.002083 0 -0 0</wrench>
        </link>
      </model>
      <model name='table'>
        <pose frame=''>0.286971 -0.023322 0 0 -0 0</pose>
        <scale>1 1 1</scale>
        <link name='link'>
          <pose frame=''>0.286971 -0.023322 0 0 -0 0</pose>
          <velocity>0 0 0 0 -0 0</velocity>
          <acceleration>0 0 0 0 -0 0</acceleration>
          <wrench>0 0 0 0 -0 0</wrench>
        </link>
      </model>
      <model name='unit_box_blue'>
        <pose frame=''>0.152226 0.070673 1.02521 -4e-06 -2.2e-05 2.8e-05</pose>
        <scale>1 1 1</scale>
        <link name='link'>
          <pose frame=''>0.152226 0.070673 1.02521 -4e-06 -2.2e-05 2.8e-05</pose>
          <velocity>0 0 0 0 -0 0</velocity>
          <acceleration>0.011022 -0.01051 0.12512 1.0294 1.07926 0</acceleration>
          <wrench>0.011022 -0.01051 0.12512 0 -0 0</wrench>
        </link>
      </model>
      <light name='sun'>
        <pose frame=''>0 0 10 0 -0 0</pose>
      </light>
    </state>
    <gui fullscreen='0'>
      <camera name='user_camera'>
        <pose frame=''>0.174386 -0.702642 6.52825 0 1.476 1.54</pose>
        <view_controller>orbit</view_controller>
        <projection_type>perspective</projection_type>
      </camera>
    </gui>
    <model name='unit_box_blue'>
      <link name='link'>
        <inertial>
          <mass>1</mass>
          <inertia>
            <ixx>0.166667</ixx>
            <ixy>0</ixy>
            <ixz>0</ixz>
            <iyy>0.166667</iyy>
            <iyz>0</iyz>
            <izz>0.166667</izz>
          </inertia>
          <pose frame=''>0 0 0 0 -0 0</pose>
        </inertial>
        <self_collide>0</self_collide>
        <enable_wind>0</enable_wind>
        <kinematic>0</kinematic>
        <pose frame=''>0 0 0 0 -0 0</pose>
        <gravity>1</gravity>
        <visual name='visual'>
          <geometry>
            <box>
              <size>0.036269 0.034595 0.020419</size>
            </box>
          </geometry>
          <material>
            <script>
              <name>Gazebo/Grey</name>
              <uri>file://media/materials/scripts/gazebo.material</uri>
            </script>
            <ambient>0 0 1 0</ambient>
            <shader type='vertex'>
              <normal_map>__default__</normal_map>
            </shader>
            <diffuse>0.7 0.7 0.7 1</diffuse>
            <specular>0.01 0.01 0.01 1</specular>
            <emissive>0 0 0 1</emissive>
          </material>
          <pose frame=''>0 0 0 0 -0 0</pose>
          <transparency>0</transparency>
          <cast_shadows>1</cast_shadows>
        </visual>
        <collision name='collision'>
          <laser_retro>0</laser_retro>
          <max_contacts>10</max_contacts>
          <pose frame=''>0 0 0 0 -0 0</pose>
          <geometry>
            <box>
              <size>0.036269 0.034595 0.020419</size>
            </box>
          </geometry>
          <surface>
            <friction>
              <ode>
                <mu>1</mu>
                <mu2>1</mu2>
                <fdir1>0 0 0</fdir1>
                <slip1>0</slip1>
                <slip2>0</slip2>
              </ode>
              <torsional>
                <coefficient>1</coefficient>
                <patch_radius>0</patch_radius>
                <surface_radius>0</surface_radius>
                <use_patch_radius>1</use_patch_radius>
                <ode>
                  <slip>0</slip>
                </ode>
              </torsional>
            </friction>
            <bounce>
              <restitution_coefficient>0</restitution_coefficient>
              <threshold>1e+06</threshold>
            </bounce>
            <contact>
              <collide_without_contact>0</collide_without_contact>
              <collide_without_contact_bitmask>1</collide_without_contact_bitmask>
              <collide_bitmask>1</collide_bitmask>
              <ode>
                <soft_cfm>0</soft_cfm>
                <soft_erp>0.2</soft_erp>
                <kp>1e+13</kp>
                <kd>1</kd>
                <max_vel>0.01</max_vel>
                <min_depth>0</min_depth>
              </ode>
              <bullet>
                <split_impulse>1</split_impulse>
                <split_impulse_penetration_threshold>-0.01</split_impulse_penetration_threshold>
                <soft_cfm>0</soft_cfm>
                <soft_erp>0.2</soft_erp>
                <kp>1e+13</kp>
                <kd>1</kd>
              </bullet>
            </contact>
          </surface>
        </collision>
      </link>
      <static>0</static>
      <allow_auto_disable>1</allow_auto_disable>
      <pose frame=''>0.024487 0.181042 1.02521 3.2e-05 1e-06 1.4e-05</pose>
    </model>
    <model name='robotic_arm'>
      <link name='camera_rgb_frame'>
        <pose frame=''>0 0 1 0 1.25 1.54</pose>
        <inertial>
          <pose frame=''>-0.0062 0 -0.0032 0 -0 0</pose>
          <mass>0.005</mass>
          <inertia>
            <ixx>0.000500205</ixx>
            <ixy>0</ixy>
            <ixz>-3.968e-07</ixz>
            <iyy>0.000500974</iyy>
            <iyz>0</iyz>
            <izz>0.000500769</izz>
          </inertia>
        </inertial>
        <collision name='camera_rgb_frame_fixed_joint_lump__camera_link_collision'>
          <pose frame=''>-0.031 0 -0.016 0 -0 0</pose>
          <geometry>
            <box>
              <size>0.07271 0.27794 0.073</size>
            </box>
          </geometry>
          <max_contacts>10</max_contacts>
          <surface>
            <contact>
              <ode/>
            </contact>
            <bounce/>
            <friction>
              <torsional>
                <ode/>
              </torsional>
              <ode/>
            </friction>
          </surface>
        </collision>
        <visual name='camera_rgb_frame_fixed_joint_lump__camera_link_visual'>
          <pose frame=''>-0.031 0 -0.016 0 -0 1.5708</pose>
          <geometry>
            <mesh>
              <scale>1 1 1</scale>
              <uri>/home/abhishek/Documents/arm4_ws/src/common_sensors/meshes/sensors/kinect.dae</uri>
            </mesh>
          </geometry>
        </visual>
        <gravity>1</gravity>
        <velocity_decay/>
        <sensor name='camera1' type='depth'>
          <always_on>1</always_on>
          <update_rate>20</update_rate>
          <camera name='__default__'>
            <horizontal_fov>1.0472</horizontal_fov>
            <image>
              <format>R8G8B8</format>
              <width>640</width>
              <height>480</height>
            </image>
            <clip>
              <near>0.05</near>
              <far>8</far>
            </clip>
          </camera>
          <plugin name='camera_depth_frame_kinect_controller' filename='libgazebo_ros_openni_kinect.so'>
            <baseline>0.1</baseline>
            <alwaysOn>1</alwaysOn>
            <updateRate>10</updateRate>
            <cameraName>camera1</cameraName>
            <imageTopicName>rgb/image_raw</imageTopicName>
            <cameraInfoTopicName>rgb/camera_info</cameraInfoTopicName>
            <depthImageTopicName>depth/image_raw</depthImageTopicName>
            <depthImageCameraInfoTopicName>depth/camera_info</depthImageCameraInfoTopicName>
            <pointCloudTopicName>depth/points</pointCloudTopicName>
            <frameName>camera_depth_optical_frame</frameName>
            <pointCloudCutoff>0.3</pointCloudCutoff>
            <distortion_k1>0.0</distortion_k1>
            <distortion_k2>0.0</distortion_k2>
            <distortion_k3>0.0</distortion_k3>
            <distortion_t1>0.0</distortion_t1>
            <distortion_t2>0.0</distortion_t2>
            <robotNamespace>/</robotNamespace>
          </plugin>
          <pose frame=''>0 0 0 0 -0 0</pose>
        </sensor>
        <self_collide>0</self_collide>
        <enable_wind>0</enable_wind>
        <kinematic>0</kinematic>
      </link>
      <joint name='camera_rgb_joint' type='fixed'>
        <child>camera_rgb_frame</child>
        <parent>world</parent>
      </joint>
      <link name='base_link'>
        <pose frame=''>0 0 0 0 -0 0</pose>
        <inertial>
          <pose frame=''>0.001448 -0.000165 0.028288 0 -0 0</pose>
          <mass>0.242599</mass>
          <inertia>
            <ixx>0.000296</ixx>
            <ixy>-0</ixy>
            <ixz>-2e-06</ixz>
            <iyy>0.000316</iyy>
            <iyz>-0</iyz>
            <izz>0.000468</izz>
          </inertia>
        </inertial>
        <collision name='base_link_collision'>
          <pose frame=''>0 0 0 0 -0 0</pose>
          <geometry>
            <mesh>
              <scale>0.001 0.001 0.001</scale>
              <uri>/home/abhishek/Documents/arm4_ws/src/arm_description/meshes/base_link.stl</uri>
            </mesh>
          </geometry>
          <surface>
            <contact>
              <ode/>
            </contact>
            <friction>
              <ode>
                <mu>0.2</mu>
                <mu2>0.2</mu2>
              </ode>
              <torsional>
                <ode/>
              </torsional>
            </friction>
            <bounce/>
          </surface>
          <max_contacts>10</max_contacts>
        </collision>
        <visual name='base_link_visual'>
          <pose frame=''>0 0 0 0 -0 0</pose>
          <geometry>
            <mesh>
              <scale>0.001 0.001 0.001</scale>
              <uri>/home/abhishek/Documents/arm4_ws/src/arm_description/meshes/base_link.stl</uri>
            </mesh>
          </geometry>
          <material>
            <script>
              <name>Gazebo/Silver</name>
              <uri>file://media/materials/scripts/gazebo.material</uri>
            </script>
          </material>
        </visual>
        <gravity>1</gravity>
        <velocity_decay/>
        <self_collide>1</self_collide>
        <gravity>1</gravity>
        <enable_wind>0</enable_wind>
        <kinematic>0</kinematic>
      </link>
      <joint name='world_to_base_link' type='fixed'>
        <child>base_link</child>
        <parent>world</parent>
      </joint>
      <link name='waist_1'>
        <pose frame=''>0.001 -0.0002 0.06 0 -0 0</pose>
        <inertial>
          <pose frame=''>-0.011987 4.5e-05 0.025606 0 -0 0</pose>
          <mass>0.160871</mass>
          <inertia>
            <ixx>0.000137</ixx>
            <ixy>0</ixy>
            <ixz>2.2e-05</ixz>
            <iyy>0.000133</iyy>
            <iyz>-0</iyz>
            <izz>0.000128</izz>
          </inertia>
        </inertial>
        <collision name='waist_1_collision'>
          <pose frame=''>-0.001 0.0002 -0.06 0 -0 0</pose>
          <geometry>
            <mesh>
              <scale>0.001 0.001 0.001</scale>
              <uri>/home/abhishek/Documents/arm4_ws/src/arm_description/meshes/waist_1.stl</uri>
            </mesh>
          </geometry>
          <surface>
            <contact>
              <ode/>
            </contact>
            <friction>
              <ode>
                <mu>0.2</mu>
                <mu2>0.2</mu2>
              </ode>
              <torsional>
                <ode/>
              </torsional>
            </friction>
            <bounce/>
          </surface>
          <max_contacts>10</max_contacts>
        </collision>
        <visual name='waist_1_visual'>
          <pose frame=''>-0.001 0.0002 -0.06 0 -0 0</pose>
          <geometry>
            <mesh>
              <scale>0.001 0.001 0.001</scale>
              <uri>/home/abhishek/Documents/arm4_ws/src/arm_description/meshes/waist_1.stl</uri>
            </mesh>
          </geometry>
          <material>
            <script>
              <name>Gazebo/Silver</name>
              <uri>file://media/materials/scripts/gazebo.material</uri>
            </script>
          </material>
        </visual>
        <gravity>1</gravity>
        <velocity_decay/>
        <self_collide>1</self_collide>
        <enable_wind>0</enable_wind>
        <kinematic>0</kinematic>
      </link>
      <joint name='rev_base' type='revolute'>
        <child>waist_1</child>
        <parent>base_link</parent>
        <axis>
          <xyz>0 0 1</xyz>
          <limit>
            <lower>-1e+16</lower>
            <upper>1e+16</upper>
          </limit>
          <dynamics>
            <damping>10</damping>
            <friction>100</friction>
            <spring_reference>0</spring_reference>
            <spring_stiffness>0</spring_stiffness>
          </dynamics>
          <use_parent_model_frame>1</use_parent_model_frame>
        </axis>
      </joint>
      <link name='arm_1_1'>
        <pose frame=''>-0.0022 -0.0002 0.10675 0 -0 0</pose>
        <inertial>
          <pose frame=''>0.01099 0 0.059205 0 -0 0</pose>
          <mass>0.0798611</mass>
          <inertia>
            <ixx>0.00014</ixx>
            <ixy>-0</ixy>
            <ixz>0</ixz>
            <iyy>0.000134</iyy>
            <iyz>0</iyz>
            <izz>1.1e-05</izz>
          </inertia>
        </inertial>
        <collision name='arm_1_1_collision'>
          <pose frame=''>0.0022 0.0002 -0.10675 0 -0 0</pose>
          <geometry>
            <mesh>
              <scale>0.001 0.001 0.001</scale>
              <uri>/home/abhishek/Documents/arm4_ws/src/arm_description/meshes/arm_1_1.stl</uri>
            </mesh>
          </geometry>
          <surface>
            <contact>
              <ode/>
            </contact>
            <friction>
              <ode>
                <mu>0.2</mu>
                <mu2>0.2</mu2>
              </ode>
              <torsional>
                <ode/>
              </torsional>
            </friction>
            <bounce/>
          </surface>
          <max_contacts>10</max_contacts>
        </collision>
        <visual name='arm_1_1_visual'>
          <pose frame=''>0.0022 0.0002 -0.10675 0 -0 0</pose>
          <geometry>
            <mesh>
              <scale>0.001 0.001 0.001</scale>
              <uri>/home/abhishek/Documents/arm4_ws/src/arm_description/meshes/arm_1_1.stl</uri>
            </mesh>
          </geometry>
          <material>
            <script>
              <name>Gazebo/Silver</name>
              <uri>file://media/materials/scripts/gazebo.material</uri>
            </script>
          </material>
        </visual>
        <gravity>1</gravity>
        <velocity_decay/>
        <self_collide>1</self_collide>
        <enable_wind>0</enable_wind>
        <kinematic>0</kinematic>
      </link>
      <joint name='rev_waist' type='revolute'>
        <child>arm_1_1</child>
        <parent>waist_1</parent>
        <axis>
          <xyz>-1 0 0</xyz>
          <limit>
            <lower>-1e+16</lower>
            <upper>1e+16</upper>
          </limit>
          <dynamics>
            <spring_reference>0</spring_reference>
            <spring_stiffness>0</spring_stiffness>
          </dynamics>
          <use_parent_model_frame>1</use_parent_model_frame>
        </axis>
      </joint>
      <link name='arm_2_1'>
        <pose frame=''>0.001 -0.0002 0.22675 0 -0 0</pose>
        <inertial>
          <pose frame=''>-0.017086 0.000108 0.031055 0 -0 0</pose>
          <mass>0.114093</mass>
          <inertia>
            <ixx>0.000121</ixx>
            <ixy>0</ixy>
            <ixz>-1.5e-05</ixz>
            <iyy>0.000129</iyy>
            <iyz>-0</iyz>
            <izz>2.8e-05</izz>
          </inertia>
        </inertial>
        <collision name='arm_2_1_collision'>
          <pose frame=''>-0.001 0.0002 -0.22675 0 -0 0</pose>
          <geometry>
            <mesh>
              <scale>0.001 0.001 0.001</scale>
              <uri>/home/abhishek/Documents/arm4_ws/src/arm_description/meshes/arm_2_1.stl</uri>
            </mesh>
          </geometry>
          <surface>
            <contact>
              <ode/>
            </contact>
            <friction>
              <ode>
                <mu>0.2</mu>
                <mu2>0.2</mu2>
              </ode>
              <torsional>
                <ode/>
              </torsional>
            </friction>
            <bounce/>
          </surface>
          <max_contacts>10</max_contacts>
        </collision>
        <visual name='arm_2_1_visual'>
          <pose frame=''>-0.001 0.0002 -0.22675 0 -0 0</pose>
          <geometry>
            <mesh>
              <scale>0.001 0.001 0.001</scale>
              <uri>/home/abhishek/Documents/arm4_ws/src/arm_description/meshes/arm_2_1.stl</uri>
            </mesh>
          </geometry>
          <material>
            <script>
              <name>Gazebo/Silver</name>
              <uri>file://media/materials/scripts/gazebo.material</uri>
            </script>
          </material>
        </visual>
        <gravity>1</gravity>
        <velocity_decay/>
        <self_collide>1</self_collide>
        <enable_wind>0</enable_wind>
        <kinematic>0</kinematic>
      </link>
      <joint name='rev_elbow' type='revolute'>
        <child>arm_2_1</child>
        <parent>arm_1_1</parent>
        <axis>
          <xyz>-1 0 0</xyz>
          <limit>
            <lower>-1e+16</lower>
            <upper>1e+16</upper>
          </limit>
          <dynamics>
            <spring_reference>0</spring_reference>
            <spring_stiffness>0</spring_stiffness>
          </dynamics>
          <use_parent_model_frame>1</use_parent_model_frame>
        </axis>
      </joint>
      <link name='arm_3_1'>
        <pose frame=''>-0.0097 0.0051 0.3165 0 -0 0</pose>
        <inertial>
          <pose frame=''>0.003061 -0.005032 0.021377 0 -0 0</pose>
          <mass>0.0295362</mass>
          <inertia>
            <ixx>7e-06</ixx>
            <ixy>-0</ixy>
            <ixz>-1e-06</ixz>
            <iyy>6e-06</iyy>
            <iyz>-0</iyz>
            <izz>4e-06</izz>
          </inertia>
        </inertial>
        <collision name='arm_3_1_collision'>
          <pose frame=''>0.0097 -0.0051 -0.3165 0 -0 0</pose>
          <geometry>
            <mesh>
              <scale>0.001 0.001 0.001</scale>
              <uri>/home/abhishek/Documents/arm4_ws/src/arm_description/meshes/arm_3_1.stl</uri>
            </mesh>
          </geometry>
          <surface>
            <contact>
              <ode/>
            </contact>
            <friction>
              <ode>
                <mu>0.2</mu>
                <mu2>0.2</mu2>
              </ode>
              <torsional>
                <ode/>
              </torsional>
            </friction>
            <bounce/>
          </surface>
          <max_contacts>10</max_contacts>
        </collision>
        <visual name='arm_3_1_visual'>
          <pose frame=''>0.0097 -0.0051 -0.3165 0 -0 0</pose>
          <geometry>
            <mesh>
              <scale>0.001 0.001 0.001</scale>
              <uri>/home/abhishek/Documents/arm4_ws/src/arm_description/meshes/arm_3_1.stl</uri>
            </mesh>
          </geometry>
          <material>
            <script>
              <name>Gazebo/Silver</name>
              <uri>file://media/materials/scripts/gazebo.material</uri>
            </script>
          </material>
        </visual>
        <gravity>1</gravity>
        <velocity_decay/>
        <self_collide>1</self_collide>
        <enable_wind>0</enable_wind>
        <kinematic>0</kinematic>
      </link>
      <joint name='rev_wrist_arm' type='revolute'>
        <child>arm_3_1</child>
        <parent>arm_2_1</parent>
        <axis>
          <xyz>0 0 1</xyz>
          <limit>
            <lower>-1e+16</lower>
            <upper>1e+16</upper>
          </limit>
          <dynamics>
            <spring_reference>0</spring_reference>
            <spring_stiffness>0</spring_stiffness>
          </dynamics>
          <use_parent_model_frame>1</use_parent_model_frame>
        </axis>
      </joint>
      <link name='flange_adaptor_2'>
        <pose frame=''>0.00565 0.0001 0.34645 0 -0 0</pose>
        <inertial>
          <pose frame=''>0.032429 0.004429 0.025805 0 -0 0</pose>
          <mass>0.0747999</mass>
          <inertia>
            <ixx>3.2e-05</ixx>
            <ixy>-5e-06</ixy>
            <ixz>-3e-06</ixz>
            <iyy>3.5e-05</iyy>
            <iyz>0</iyz>
            <izz>4.4e-05</izz>
          </inertia>
        </inertial>
        <collision name='flange_adaptor_2_collision'>
          <pose frame=''>-0.00565 -0.0001 -0.34645 0 -0 0</pose>
          <geometry>
            <mesh>
              <scale>0.001 0.001 0.001</scale>
              <uri>/home/abhishek/Documents/arm4_ws/src/arm_description/meshes/flange_adaptor_2.stl</uri>
            </mesh>
          </geometry>
          <surface>
            <contact>
              <ode/>
            </contact>
            <friction>
              <ode>
                <mu>1</mu>
                <mu2>1</mu2>
              </ode>
              <torsional>
                <ode/>
              </torsional>
            </friction>
            <bounce/>
          </surface>
          <max_contacts>10</max_contacts>
        </collision>
        <visual name='flange_adaptor_2_visual'>
          <pose frame=''>-0.00565 -0.0001 -0.34645 0 -0 0</pose>
          <geometry>
            <mesh>
              <scale>0.001 0.001 0.001</scale>
              <uri>/home/abhishek/Documents/arm4_ws/src/arm_description/meshes/flange_adaptor_2.stl</uri>
            </mesh>
          </geometry>
          <material>
            <script>
              <name>Gazebo/Silver</name>
              <uri>file://media/materials/scripts/gazebo.material</uri>
            </script>
          </material>
        </visual>
        <gravity>1</gravity>
        <velocity_decay/>
        <self_collide>1</self_collide>
        <enable_wind>0</enable_wind>
        <kinematic>0</kinematic>
      </link>
      <joint name='rev_effector' type='revolute'>
        <child>flange_adaptor_2</child>
        <parent>arm_3_1</parent>
        <axis>
          <xyz>1 0 0</xyz>
          <limit>
            <lower>-1e+16</lower>
            <upper>1e+16</upper>
          </limit>
          <dynamics>
            <spring_reference>0</spring_reference>
            <spring_stiffness>0</spring_stiffness>
          </dynamics>
          <use_parent_model_frame>1</use_parent_model_frame>
        </axis>
      </joint>
      <link name='grip_finger_left_2'>
        <pose frame=''>0.05095 0.0326 0.388581 0 -0 0</pose>
        <inertial>
          <pose frame=''>-0.0147 -0.008314 0.008946 0 -0 0</pose>
          <mass>0.0102843</mass>
          <inertia>
            <ixx>3e-06</ixx>
            <ixy>0</ixy>
            <ixz>-1e-06</ixz>
            <iyy>3e-06</iyy>
            <iyz>0</iyz>
            <izz>1e-06</izz>
          </inertia>
        </inertial>
        <collision name='grip_finger_left_2_collision'>
          <pose frame=''>-0.05095 -0.0326 -0.388581 0 -0 0</pose>
          <geometry>
            <mesh>
              <scale>0.001 0.001 0.001</scale>
              <uri>/home/abhishek/Documents/arm4_ws/src/arm_description/meshes/grip_finger_left_2.stl</uri>
            </mesh>
          </geometry>
          <surface>
            <contact>
              <ode/>
            </contact>
            <friction>
              <ode>
                <mu>0.2</mu>
                <mu2>0.2</mu2>
              </ode>
              <torsional>
                <ode/>
              </torsional>
            </friction>
            <bounce/>
          </surface>
          <max_contacts>10</max_contacts>
        </collision>
        <visual name='grip_finger_left_2_visual'>
          <pose frame=''>-0.05095 -0.0326 -0.388581 0 -0 0</pose>
          <geometry>
            <mesh>
              <scale>0.001 0.001 0.001</scale>
              <uri>/home/abhishek/Documents/arm4_ws/src/arm_description/meshes/grip_finger_left_2.stl</uri>
            </mesh>
          </geometry>
          <material>
            <script>
              <name>Gazebo/Silver</name>
              <uri>file://media/materials/scripts/gazebo.material</uri>
            </script>
          </material>
        </visual>
        <gravity>1</gravity>
        <velocity_decay/>
        <self_collide>1</self_collide>
        <enable_wind>0</enable_wind>
        <kinematic>0</kinematic>
      </link>
      <joint name='lfinger_slider' type='prismatic'>
        <child>grip_finger_left_2</child>
        <parent>flange_adaptor_2</parent>
        <axis>
          <xyz>0 -1 0</xyz>
          <limit>
            <lower>0</lower>
            <upper>0.0175</upper>
            <effort>100</effort>
            <velocity>100</velocity>
          </limit>
          <dynamics>
            <spring_reference>0</spring_reference>
            <spring_stiffness>0</spring_stiffness>
          </dynamics>
          <use_parent_model_frame>1</use_parent_model_frame>
        </axis>
      </joint>
      <link name='grip_finger_right_2'>
        <pose frame=''>0.05095 -0.0324 0.388581 0 -0 0</pose>
        <inertial>
          <pose frame=''>-0.0132 0.006866 0.013584 0 -0 0</pose>
          <mass>0.00872141</mass>
          <inertia>
            <ixx>1e-06</ixx>
            <ixy>-0</ixy>
            <ixz>-0</ixz>
            <iyy>2e-06</iyy>
            <iyz>-0</iyz>
            <izz>1e-06</izz>
          </inertia>
        </inertial>
        <collision name='grip_finger_right_2_collision'>
          <pose frame=''>-0.05095 0.0324 -0.388581 0 -0 0</pose>
          <geometry>
            <mesh>
              <scale>0.001 0.001 0.001</scale>
              <uri>/home/abhishek/Documents/arm4_ws/src/arm_description/meshes/grip_finger_right_2.stl</uri>
            </mesh>
          </geometry>
          <surface>
            <contact>
              <ode/>
            </contact>
            <friction>
              <ode>
                <mu>1</mu>
                <mu2>1</mu2>
              </ode>
              <torsional>
                <ode/>
              </torsional>
            </friction>
            <bounce/>
          </surface>
          <max_contacts>10</max_contacts>
        </collision>
        <visual name='grip_finger_right_2_visual'>
          <pose frame=''>-0.05095 0.0324 -0.388581 0 -0 0</pose>
          <geometry>
            <mesh>
              <scale>0.001 0.001 0.001</scale>
              <uri>/home/abhishek/Documents/arm4_ws/src/arm_description/meshes/grip_finger_right_2.stl</uri>
            </mesh>
          </geometry>
          <material>
            <script>
              <name>Gazebo/Silver</name>
              <uri>file://media/materials/scripts/gazebo.material</uri>
            </script>
          </material>
        </visual>
        <gravity>1</gravity>
        <velocity_decay/>
        <self_collide>1</self_collide>
        <enable_wind>0</enable_wind>
        <kinematic>0</kinematic>
      </link>
      <joint name='rfinger_slider' type='prismatic'>
        <child>grip_finger_right_2</child>
        <parent>flange_adaptor_2</parent>
        <axis>
          <xyz>0 1 0</xyz>
          <limit>
            <lower>0</lower>
            <upper>0.0175</upper>
            <effort>100</effort>
            <velocity>100</velocity>
          </limit>
          <dynamics>
            <spring_reference>0</spring_reference>
            <spring_stiffness>0</spring_stiffness>
          </dynamics>
          <use_parent_model_frame>1</use_parent_model_frame>
        </axis>
      </joint>
      <plugin name='control' filename='libgazebo_ros_control.so'>
        <robotNamespace>/</robotNamespace>
      </plugin>
      <static>0</static>
      <plugin name='gazebo_grasp_fix' filename='libgazebo_grasp_fix.so'>
        <arm>
          <arm_name>arm</arm_name>
          <palm_link>flange_adaptor_2</palm_link>
          <gripper_link>grip_finger_right_2</gripper_link>
          <gripper_link>grip_finger_left_2</gripper_link>
        </arm>
        <forces_angle_tolerance>100</forces_angle_tolerance>
        <update_rate>4</update_rate>
        <grip_count_threshold>4</grip_count_threshold>
        <max_grip_count>8</max_grip_count>
        <release_tolerance>0.005</release_tolerance>
        <disable_collisions_on_attach>0</disable_collisions_on_attach>
        <contact_topic>__default_topic__</contact_topic>
        <robotNamespace>/</robotNamespace>
      </plugin>
      <pose frame=''>0 0 1.06 0 -0 0</pose>
    </model>
  </world>
</sdf>
